Traceback (most recent call last):
  File "/home/codespace/.local/lib/python3.12/site-packages/jupyter_core/utils/__init__.py", line 154, in wrapped
    asyncio.get_running_loop()
RuntimeError: no running event loop

During handling of the above exception, another exception occurred:

Traceback (most recent call last):
  File "/usr/local/python/3.12.1/lib/python3.12/site-packages/jupyter_cache/executors/utils.py", line 58, in single_nb_execution
    executenb(
  File "/home/codespace/.local/lib/python3.12/site-packages/nbclient/client.py", line 1319, in execute
    return NotebookClient(nb=nb, resources=resources, km=km, **kwargs).execute()
           ^^^^^^^^^^^^^^^^^^^^^^^^^^^^^^^^^^^^^^^^^^^^^^^^^^^^^^^^^^^^^^^^^^^^^
  File "/home/codespace/.local/lib/python3.12/site-packages/jupyter_core/utils/__init__.py", line 158, in wrapped
    return loop.run_until_complete(inner)
           ^^^^^^^^^^^^^^^^^^^^^^^^^^^^^^
  File "/usr/local/python/3.12.1/lib/python3.12/asyncio/base_events.py", line 684, in run_until_complete
    return future.result()
           ^^^^^^^^^^^^^^^
  File "/home/codespace/.local/lib/python3.12/site-packages/nbclient/client.py", line 709, in async_execute
    await self.async_execute_cell(
  File "/home/codespace/.local/lib/python3.12/site-packages/nbclient/client.py", line 1062, in async_execute_cell
    await self._check_raise_for_error(cell, cell_index, exec_reply)
  File "/home/codespace/.local/lib/python3.12/site-packages/nbclient/client.py", line 918, in _check_raise_for_error
    raise CellExecutionError.from_cell_and_msg(cell, exec_reply_content)
nbclient.exceptions.CellExecutionError: An error occurred while executing the following cell:
------------------
import pandas as pd
import numpy as np
import matplotlib.pyplot as plt
import seaborn as sns
#import plotly.express as px
import statsmodels.api as sm
from statsmodels.formula.api import ols
import scipy.stats as stats
------------------


[31m---------------------------------------------------------------------------[39m
[31mModuleNotFoundError[39m                       Traceback (most recent call last)
[36mCell[39m[36m [39m[32mIn[1][39m[32m, line 6[39m
[32m      4[39m [38;5;28;01mimport[39;00m[38;5;250m [39m[34;01mseaborn[39;00m[38;5;250m [39m[38;5;28;01mas[39;00m[38;5;250m [39m[34;01msns[39;00m
[32m      5[39m [38;5;66;03m#import plotly.express as px[39;00m
[32m----> [39m[32m6[39m [38;5;28;01mimport[39;00m[38;5;250m [39m[34;01mstatsmodels[39;00m[34;01m.[39;00m[34;01mapi[39;00m[38;5;250m [39m[38;5;28;01mas[39;00m[38;5;250m [39m[34;01msm[39;00m
[32m      7[39m [38;5;28;01mfrom[39;00m[38;5;250m [39m[34;01mstatsmodels[39;00m[34;01m.[39;00m[34;01mformula[39;00m[34;01m.[39;00m[34;01mapi[39;00m[38;5;250m [39m[38;5;28;01mimport[39;00m ols
[32m      8[39m [38;5;28;01mimport[39;00m[38;5;250m [39m[34;01mscipy[39;00m[34;01m.[39;00m[34;01mstats[39;00m[38;5;250m [39m[38;5;28;01mas[39;00m[38;5;250m [39m[34;01mstats[39;00m

[31mModuleNotFoundError[39m: No module named 'statsmodels'

